<?xml version="1.0"?>
<robot xmlns:xacro="http://ros.org/wiki/xacro">
<!-- <robot xmlns:sensor="http://playerstage.sourceforge.net/gazebo/xmlschema/#sensor"
       xmlns:controller="http://playerstage.sourceforge.net/gazebo/xmlschema/#controller"
       xmlns:interface="http://playerstage.sourceforge.net/gazebo/xmlschema/#interface"
       xmlns:xacro="http://ros.org/wiki/xacro"> -->

	<xacro:include filename="$(find dlr_description)/urdf/hit2/hit2.gazebo.xacro" />
	<xacro:include filename="$(find dlr_description)/urdf/hit2/hit2.transmission.xacro" />

	<xacro:property name="damping_all" value="1" />
	<xacro:property name="pi" value="3.1415926535897931" />
	<xacro:property name="abd_lb" value="-20" />
	<xacro:property name="abd_ub" value="20" />
	<xacro:property name="inner_lb" value="0" />
	<xacro:property name="inner_ub" value="75" />
	<xacro:property name="outer_lb" value="0" />
	<xacro:property name="outer_ub" value="75" />
	<!-- inertia_scale : from kg*mm^2 to kg*m^2 -->
	<xacro:property name="inertia_scale" value="0.000001" />
	<xacro:property name="velocity" value="5" />
	<xacro:property name="effort" value="100" />

	<xacro:macro name="dlr_hit2_finger" params="parent name position orientation damping">
		<!-- macro for one finger -->

		<!-- abductor joint between palm_link and finger_abd_link - fake between palm and proximal -->
		<joint name="${name}_abd_joint" type="revolute">
			<origin xyz="${position}" rpy="${orientation}" />
			<parent link="${parent}"/>
			<child link="${name}_abd_link"/>
			<axis xyz="0 0 1" />
			<dynamics damping="${damping}" />
			<limit lower="${abd_lb * pi / 180}" upper="${abd_ub * pi / 180}" effort="${effort}" velocity="${velocity}"/> <!-- effort="100" velocity="5" -->
		</joint>

		<link name="${name}_abd_link">
<!-- 			<inertial>
				<origin xyz="0 0 0" rpy="0 0 0"/>
				<mass value="0.0"/>
				<inertia ixx="0" ixy="0" ixz="0" iyy="0" iyz="0" izz="0" />
			</inertial> -->
			<!-- possibly add basecover.stl as both geometry and collision... -->
			<visual>
				<origin xyz="0 0 0" rpy="0 0 0" />
				<geometry>
					<mesh filename="package://dlr_description/meshes/hit2/base.stl" />
				</geometry>
			<material name="DLR/LightGrey" />
			</visual>
		</link>

		<!-- inner joint between abd_link and proximal_link -->
		<joint name="${name}_inner_joint" type="revolute">
			<!-- coincident with abd_joint, rotated of 90 degrees along x -->
			<origin xyz="0 0 0" rpy="${pi/2} 0 0" />
			<parent link="${name}_abd_link"/>
			<child link="${name}_proximal_link"/>
			<axis xyz="0 0 1" />
			<dynamics damping="${damping}" />
			<limit lower="${inner_lb * pi / 180}" upper="${inner_ub * pi / 180}" effort="${effort}" velocity="${velocity}"/> <!-- effort="100" velocity="5" -->
		</joint>

		<link name="${name}_proximal_link">
			<!-- <inertial>
				<origin xyz="30.164510e -1.0130813 0.50813186" rpy="0 0 0"/>
				<mass value="0.044370598"/>
				<inertia ixx="${inertia_scale * 4.5592704}" ixy="${inertia_scale * 0.90783105}" ixz="${inertia_scale * (-0.9399771)}" iyy="${inertia_scale * 49.045259}" iyz="${inertia_scale * 0.017052714}" izz="${inertia_scale * 50.524234}" />
			</inertial> -->
			
			<visual>
				<origin xyz="0 0 0" rpy="0 0 0" />
				<geometry>
					<mesh filename="package://dlr_description/meshes/hit2/proximal.stl" />
				</geometry>
			<material name="DLR/LightGrey" />
			</visual>
			
<!-- 			<collision>
				<origin xyz="0 0 0" rpy="0 0 0" />
				<geometry>
					<mesh filename="package://dlr_description/meshes/hit2/phalanx_proximal.stl"/>
				</geometry>
			</collision> -->
		</link>

		<!-- outer1 joint between proximal_link and medial_link -->
		<joint name="${name}_outer1_joint" type="revolute">
			 
			<origin xyz="0.055 0 0" rpy="0 0 0" />
			<parent link="${name}_proximal_link"/>
			<child link="${name}_medial_link"/>
			<axis xyz="0 0 1" />
			<dynamics damping="${damping}" />
			<limit lower="${outer_lb * pi / 180}" upper="${outer_ub * pi / 180}" effort="${effort}" velocity="${velocity}"/> <!-- effort="100" velocity="5" -->
		</joint>

		<link name="${name}_medial_link">
			<!-- <inertial>
			<origin xyz="5.7271879 -1.6164173 -1.1567914" rpy="0 0 0"/>
				<mass value="0.027110192"/>
				<inertia ixx="${inertia_scale * 2.2900229}" ixy="${inertia_scale * 0.40604622}" ixz="${inertia_scale * 0.14362094}" iyy="${inertia_scale * 4.2155489}" iyz="${inertia_scale * (-0.043115648)}" izz="${inertia_scale * 4.4292927}" />
			</inertial> -->
			
			<visual>
				<origin xyz="0 0 0" rpy="0 0 0" />
				<geometry>
					<mesh filename="package://dlr_description/meshes/hit2/medial.stl" />
				</geometry>
			<material name="DLR/LightGrey" />
			</visual>
			
			<collision>
				<origin xyz="0 0 0" rpy="0 0 0" />
				<geometry>
					<mesh filename="package://dlr_description/meshes/hit2/medial.stl"/>
				</geometry>
			</collision>
		</link>

		<!-- outer2 joint between medial_link and distal_link -->
		<joint name="${name}_outer2_joint" type="revolute">
			 
			<origin xyz="0.025 0 0" rpy="0 0 ${- pi / 2}" />
			<parent link="${name}_medial_link"/>
			<child link="${name}_distal_link"/>
			<axis xyz="0 0 1" />
			<dynamics damping="${damping}" />
			<limit lower="${outer_lb * pi / 180}" upper="${outer_ub * pi / 180}" effort="${effort}" velocity="${velocity}"/> <!-- effort="100" velocity="5" -->
		</joint>

		<link name="${name}_distal_link">
			<!-- <inertial>
			<origin xyz="-0.83348211 6.1007977 1.7728256" rpy="0 0 0"/>
				<mass value="0.018179709"/>
				<inertia ixx="${inertia_scale * 2.5867271}" ixy="${inertia_scale * 0.15840536}" ixz="${inertia_scale * (-0.00078205885)}" iyy="${inertia_scale * 0.84596248}" iyz="${inertia_scale * (-0.0048358115)}" izz="${inertia_scale * 2.5838485}" />
			</inertial> -->
			
			<visual>
				<origin xyz="0 0 0" rpy="0 0 0" />
				<geometry>
					<mesh filename="package://dlr_description/meshes/hit2/distal.stl" />
				</geometry>
			<material name="DLR/LightGrey" />
			</visual>
			
			<collision>
				<origin xyz="0 0 0" rpy="0 0 0" />
				<geometry>
					<mesh filename="package://dlr_description/meshes/hit2/distal.stl"/>
				</geometry>
			</collision>
		</link>

	</xacro:macro>

	<xacro:macro name="dlr_hit2" params="parent name *origin">
		<!-- macro for the hand -->

		<!-- joint between arm_end_effector and hit2_palm_link -->
		<joint name="${name}_palm_joint" type="fixed" >
			<insert_block name="origin" />
			<parent link="${parent}" />
			<child link="${name}_palm_link" />
		</joint>

		<link name="${name}_palm_link">
			<!-- <inertial> -->
				<!-- PALM MASS AND INERTIA TO BE ESTIMATED!!!! -->
				<!-- <origin xyz="0 0 0" rpy="0 0 0"/>
				<mass value="1"/>
				<inertia ixx="0.01" ixy="0" ixz="0" iyy="0.01" iyz="0" izz="0.01" />
			</inertial> -->
			
			<!-- also check whether is ok to leave at zero the origin -->
			<visual>
				<origin xyz="0 0 0" rpy="0 0 0" />
				<geometry>
					<mesh filename="package://dlr_description/meshes/hit2/palm.stl" />
				</geometry>
				<material name="DLR/LightGrey" />
			</visual>
			
			<collision>
				<origin xyz="0 0 0" rpy="0 0 0" />
				<geometry>
					<mesh filename="package://dlr_description/meshes/hit2/palm.stl"/>
				</geometry>
			</collision>
		</link>
		
		<!-- <xacro:macro name="dlr_hit2_finger" params="parent name position orientation damping"> -->
		<!-- macro for each finger -->
		<xacro:dlr_hit2_finger parent="${name}_palm_link" name="${name}_thumb" position="0.062569057 0.044544548 0.080044647" orientation="0.41136 -1.08366 0.225804" damping="${damping_all}" />
	
		<xacro:dlr_hit2_finger parent="${name}_palm_link" name="${name}_index" position="-0.002529881 0.036800135 0.108743545" orientation="3.05433 -${pi/2} 0" damping="${damping_all}" />
	
		<xacro:dlr_hit2_finger parent="${name}_palm_link" name="${name}_middle" position="-0.0037 0.01 0.119043545" orientation="${pi} -${pi/2} 0" damping="${damping_all}" />
	
		<xacro:dlr_hit2_finger parent="${name}_palm_link" name="${name}_ring" position="-0.002529881 -0.016800135 0.114043545" orientation="-3.05433 -${pi/2} 0" damping="${damping_all}" />
	
		<xacro:dlr_hit2_finger parent="${name}_palm_link" name="${name}_pinky" position="0.000971571 -0.043396306 0.095043545" orientation="-2.96706 -${pi/2} 0" damping="${damping_all}" />
	
		<!-- extensions -->
		<xacro:dlr_hit2_gazebo name="${name}" />
		<xacro:dlr_hit2_transmission name="${name}" />

	</xacro:macro>

</robot>
